Workbook
Name Ceph_10K_Skylake: '[1]Storage-Compute'!$C$9:$C$11
Name Ceph_Broadwell: '[1]Storage-Compute'!$C$9:$C$11
Name Ceph_Skylake: '[1]Storage-Compute'!$C$9:$C$11
Name Ceph_Skylake_IBRS: '[1]Storage-Compute'!$C$45:$C$46
Name Ceph_Skylake_IBRS_VTM: '[1]Storage-Compute'!$C$47:$C$48
Name Ceph_VTM: '[1]Storage-Compute'!$C$12:$C$13
Name Cisco_2020_HLC: '[1]Storage-Compute'!$B$45:$B$65
Name Cisco_2020_HLC_image: '[1]Image-Cloud '!$B$20:$B$29
Name Cloud_HHT: '[1]Storage-Compute'!$B$70:$B$74
Name Cloud_HHT_image: '[1]Image-Cloud '!$B$36:$B$43
Name Cloud_VTT: '[1]Storage-Compute'!$B$82
Name Cloud_VTT_image: '[1]Image-Cloud '!$B$45:$B$50
Name Dell_Unity_186_G05: '[1]Storage-Compute'!$C$23:$C$29
Name Hitachi_135_H11: '[1]Storage-Compute'!$C$30:$C$32
Name Hitachi_G700_Skylake_IBRS: '[1]Storage-Compute'!$C$58:$C$59
Name HP_3PAR_C01_Broadwell: '[1]Storage-Compute'!$C$14:$C$16
Name HP_3PAR_C01_Skylake: '[1]Storage-Compute'!$C$14:$C$16
Name HP_3PAR_E04: '[1]Storage-Compute'!$C$17:$C$18
Name HP_3PAR_E06_VTT: '[1]Storage-Compute'!$C$19:$C$20
Name HPE_2019_HLC: '[1]Storage-Compute'!$B$9:$B$21
Name HPE_2019_HLC_image: '[1]Image-Cloud '!$B$9:$B$17
Name HPE_3PAR_T6H09_Skylake_IBRS_VTT: '[1]Storage-Compute'!$C$55:$C$56
Name IBM_V7000_03_T5: '[1]Storage-Compute'!$C$21
Name IBM_V7000_T5: '[1]Storage-Compute'!$C$22
Name IBM_V7000_VTS: '[1]Storage-Compute'!$C$29
Name KGM_HHT_Ceph_2022_Q1_01: '[1]Storage-Compute'!$C$72:$C$73
Name Tu_Muon: '[1]Storage-Compute'!$C$33
Name UNITY880_01_Skylake_IBRS: '[1]Storage-Compute'!$C$57
Name UNITY880_01_Skylake_IBRS_VTS_Private: '[1]Storage-Compute'!$C$57
Name UNITY880_01_Skylake_IBRS_VTS_Public: '[1]Storage-Compute'!$C$57
Name ViettelPay_PCI_DSS: '[1]Storage-Compute'!$B$36:$B$38
Name ViettelPay_PCI_DSS_image: '[1]Image-Cloud '!$B$32:$B$34
Name VTNet_Ceph_2021_Q2_01: '[1]Storage-Compute'!$C$49:$C$52
Name VTNet_Ceph_2021_Q2_02: '[1]Storage-Compute'!$C$49:$C$52
Name VTNet_HHT_Ceph_2021_Q3_01: '[1]Storage-Compute'!$C$70:$C$71
Name VTNet_HHT_Ceph_2022_Q1_01: '[1]Storage-Compute'!$C$70:$C$71
Name VTNet_HHT_SAN_2021_Q3_01: '[1]Storage-Compute'!$C$74
Name VTNet_HHT_SAN_2022_Q2_01: '[1]Storage-Compute'!$C$75
Name VTNet_SAN_2021_Q2_01: '[1]Storage-Compute'!$C$53:$C$54
Name VTNet_SAN_2021_Q2_02: '[1]Storage-Compute'!$C$53:$C$54
Name VTNet_SAN_2021_Q2_03: '[1]Storage-Compute'!$C$60
Name VTNet_SAN_2021_Q2_04: '[1]Storage-Compute'!$C$61
Name VTNet_SAN_2021_Q3_01: '[1]Storage-Compute'!$C$62
Name VTNet_SAN_2022_Q1_01: '[1]Storage-Compute'!$C$63
Name VTP_CDE: '[1]Storage-Compute'!$C$36:$C$37
Name VTP_NCDE: '[1]Storage-Compute'!$C$36:$C$37
Name VTP_OTH: '[1]Storage-Compute'!$C$36:$C$37
Name VTS_Ceph_2021_Q2_01: '[1]Storage-Compute'!$C$49:$C$52
Name VTS_SAN_2021_Q2_01: '[1]Storage-Compute'!$C$53:$C$54
Name VTS_SAN_2021_Q2_02: '[1]Storage-Compute'!$C$61
Name VTS_SAN_2021_Q2_03: '[1]Storage-Compute'!$C$60
Name VTT_SAN_2021_Q2_01: '[1]Storage-Compute'!$C$53:$C$54
Name VTT_SAN_2021_Q2_02: '[1]Storage-Compute'!$C$53:$C$54
Name VTT_SAN_2021_Q4_01: '[1]Storage-Compute'!$C$82:$C$85

Sheet Sizing
A1: STT | B1: Mã PYC | C1: Đơn vị | D1: Đầu mối tạo PYC | E1: Đầu mối xử lý | F1: Trạng thái | G1: Thời điểm đẩy yêu cầu | H1: Thời gian hoàn thành theo KPI | I1: Thời gian hoàn thành ký PNX và đóng y/c | J1: Chất lượng sizing (false) | K1: Số lần sizing qua mail | L1: Thời gian ký bản chốt sizing | M1: Tên dự án - Mục đích sizing | N1: Ghi chú
A2: 1 | B2: 4140334 | D2: sonht2 | E2: tannph | F2: Hoàn thành | G2: 44970 | H2: 44973 | I2: 44973 | M2: Logkpi TV360
A3: 2 | B3: 4140332 | D3: sonht2 | E3: hungnn27 | F3: Hoàn thành | G3: 44970 | H3: 44973 | I3: 44973 | M3: backend TV360
A4: 3 | B4: 4145107 | D4: anhnt576 | E4: tannph | F4: Hoàn thành | G4: 44985 | H4: 44988 | I4: 44986 | M4: CCAI API
A5: 4 | B5: 4145808 | D5: tuyenpv9 | E5: hungnn27 | F5: Hoàn thành | G5: 44987 | H5: 44992 | I5: 44991 | M5: VoiceBrandname
A6: 5 | B6: 4148244 | D6: Dungha7 | E6: ductn | F6: Hoàn thành | G6: 44998 | H6: 45001 | I6: 45001 | M6: sizing CCAI giai đoạn 2
A7: 6 | B7: 4148678 | D7: quanhh3 | E7: hieuhv13 | F7: Hoàn thành | G7: 44999 | H7: 45002 | I7: 45002 | M7: sizing hệ thống Payment 2
A8: 7 | B8: 4149626 | D8: tuyenpv9 | E8: hungd | F8: Hoàn thành | G8: 45001 | H8: 45006 | I8: 45006 | M8: Thẩm định sizing Voice Brandname (bổ sung vaspgw_cdr và vaspgw_log)
A9: 8 | B9: 4149624 | D9: tuyenpv9 | E9: hungd | F9: Hoàn thành | G9: 45001 | H9: 45006 | I9: 45006 | M9: Thẩm định sizing Voice Brandname (bổ sung vaspgw)
A10: 9 | B10: 4151337 | D10: tamdtt1 | E10: ductn | F10: Hoàn thành | G10: 45006 | H10: 45008 | I10: 45008 | M10: Thẩm Định lại Sizing Kafka (Vtracking)
A11: 10 | B11: 4153924 | D11: chinh3 | E11: ductn | F11: Hoàn thành | G11: 45016 | H11: 45020 | I11: 45020 | M11: Thẩm định tài liệu định cỡ tài nguyên Quầy dịch vụ viễn thông tự động
A12: 11 | B12: 4155624 | D12: tiendd | E12: hieuhv13 | F12: Hoàn thành | G12: 45023 | H12: 45027 | I12: 45027 | M12: Sizing hệ thống TMS VHT
A13: 12 | B13: 4156658 | D13: tamdtt1 | E13: ductn | F13: Hoàn thành | G13: 45028 | H13: 45030 | I13: 45030 | M13: Thẩm định sizing hệ thống Camera giám sát
... A27: 26 | B27: 4173640 | D27: trangtth11 | E27: vinhtq18 | F27: Hoàn thành | G27: 45089 | H27: 45091 | I27: 45092 | M27: Thẩm định sizing hệ thống vHealth
A28: 27 | B28: 4175442 | D28: dattht | E28: hoangld2 | F28: Hoàn thành | G28: 45093 | H28: 45097 | I28: 45096 | M28: Thẩm định sizing dự án vcontract nâng cấp bổ sung phương án kinh doanh mới
A29: 28 | B29: 4176326 | D29: duongvx | E29: ductn | F29: Hoàn thành | G29: 45096 | H29: 45099 | I29: 45097 | M29: Thẩm định sizing dự án hệ thống quản lý thuê bao IoT_CMP của VHT
A30: 29 | B30: 4178224 | D30: dattht | E30: vinhtq18 | F30: Hoàn thành | G30: 45098 | H30: 45100 | I30: 45099 | M30: Thẩm định sizing định cỡ trái tim cho em
A31: 30 | B31: 4179410 | D31: quanhh3 | E31: ductn | F31: Hoàn thành | G31: 45100 | H31: 45103 | I31: 45103 | M31: sizing hệ thống ussd199/pay199
A32: 31 | B32: 4180498 | D32: duongvx | E32: ductn | F32: Hoàn thành | G32: 45105 | H32: 45108 | I32: 45112 | M32: Thẩm định sizing dự án hệ thống quản lý thuê bao IoT_CMP của VHT | N32: Trao đổi qua điện thoại
A33: 32 | B33: 4182686 | D33: hainv71 | E33: hieuhv13 | F33: Trao đôi trực tiếp | G33: 45114 | H33: 45118 | I33: 45121 | M33: Sizing log, backup DB HDDT
A34: 33 | B34: 4183198 | D34: thund1 | E34: ductn | F34: Hoàn thành | G34: 45117 | H34: 45119 | I34: 45118 | M34: PYC Sizing của vTracking 2.0
A35: 34 | B35: 4183199 | D35: anhnt576 | E35: vinhtq18 | F35: Hoàn thành | G35: 45117 | H35: 45119 | I35: 45125 | M35: Thẩm định sizing phân hệ Dagoras ARPU
A36: 35 | B36: 4183212 | D36: dattht | E36: hoangld2 | F36: Hoàn thành | G36: 45117 | H36: 45119 | I36: 45135 | M36: Thẩm định sizing dự án vcontract phương án kinh doanh nội bộ
A37: 36 | B37: 4187821 | D37: hienlt15 | E37: hieuhv13 | F37: Hoàn thành | G37: 45127 | H37: 45130 | I37: 45131 | M37: Thẩm định sizing hệ thống hóa đơn điện tử : database truyền nhận lần 4
A38: 37 | B38: 4188679 | D38: ngoctv1 | E38: vinhtq18 | F38: Hoàn thành | G38: 45131 | H38: 45133 | I38: 45135 | M38: Sizing Bổ sung phần lưu trữ backup và cụm XDR cho db Aerospike của myviettel
A39: 38 | B39: 4189869 | D39: hieund28 | E39: hoangld2 | F39: Hoàn thành | G39: 45135 | H39: 45139 | I39: 45138 | M39: Thẩm định Sizing hệ thống RATING
A40: 39 | B40: 4198143 | D40: soncn2 | E40: ductn | F40: Hoàn thành | G40: 45163 | H40: 45167 | I40: 45166 | M40: Hỗ trợ thẩm định sizing môi trường test hệ thống Roaming 2.0
A41: 40 | B41: 4198497 | D41: tuyenvm | E41: vinhtq18 | F41: Hoàn thành | G41: 45166 | H41: 45168 | I41: 45167 | M41: sizing hệ thống BCCS_CA chuyển đổi K8s (Hệ thống TEST)
A42: 41 | B42: 4199290 | D42: chinh3 | E42: vinhtq18 | F42: Hoàn thành | G42: 45167 | H42: 45174 | I42: 45174 | M42: Thẩm định tài liệu định cỡ tài nguyên lưu trữ hệ thống QLSX VTT mới
A43: 42 | B43: 4199538 | D43: TUYENVM | E43: vinhtq18 | F43: Hoàn thành | G43: 45175 | H43: 45177 | I43: 45177 | M43: PYC sizing hệ thống BCCS_CA chuyển đổi K8s (Hệ thống TEST) lần 2
A44: 43 | B44: PYC-743 | D44: hoangnt21 | E44: hoangld2 | F44: Hoàn thành | G44: 45176 | H44: 45179 | I44: 45180 | M44: Thẩm định sizing để xin bổ sung tài nguyên cho HTĐS Trong nước tránh cao tải CPU, RAM
A45: 44 | B45: 4199082 | D45: kientt6 | E45: ductn | F45: Hoàn thành | G45: 45239 | H45: 13/09/2023 | I45: 45269 | M45: PYC thẩm định sizing bổ sung cho hệ thống Callbot (đã ký). | N45: Thời gian thực hiện thay đổi do đội dự án điền sai loại yêu cầu
A46: 45 | B46: 4200717 | D46: sonht2 | E46: hieuhv13 | F46: Hoàn thành | G46: 15/09/2023 | H46: 19/09/2023 | I46: 19/09/2023 | M46: Thẩm định sizing Backend TV360 toàn cầu
A47: 46 | B47: 4201635 | D47: tuyenvm | E47: vinhtq18 | F47: Hoàn thành | G47: 22/09/2023 | H47: 26/09/2023 | I47: 26/09/2023 | M47: PYC sizing hệ thống BCCS_CA chuyển đổi K8s (Hệ thống TEST)
A48: 47 | B48: 4200717 | D48: sonht2 | E48: hieuhv13 | F48: Hoàn thành | G48: 45087 | H48: 45179 | I48: 45240 | M48: Thẩm định sizing Backend TV360 toàn cầu lan 2
A49: 48 | B49: PYC-3146 | D49: tiendc | E49: hoangld2 | F49: Hoàn thành | G49: 45209 | H49: 13/10/2023 | I49: 45240 | M49: Đánh giá sizing FTP server hệ thống Quản lý hồ sơ
A50: 49 | B50: PYC-3240 | D50: hieund28 | E50: ductn | F50: Hoàn thành | G50: 45270 | H50: 17/10/2023 | I50: 16/10/2023 | M50: DAC][FMRA] Đánh giá sizing cho hệ thống RATING
A51: 50 | B51: PYC-3585 | D51: hoabv8 | E51: ductn | F51: Hoàn thành | G51: 20/10/2023 | H51: 24/10/2023 | I51: 20/10/2023 | M51: Thẩm định sizing để xin bổ sung tài nguyên cho SmartMotor
A52: 51 | B52: Mail | D52: khanhnn25 | E52: hieuhv13 | F52: Hoàn thành | G52: 23/10/2023 | H52: 25/10/2023 | I52: 24/10/2023 | M52: Sizing hệ thống Viettel safe platform
A53: 52 | B53: PYC-3910 | D53: tamddt1 | E53: ductn | F53: Hoàn thành | G53: 25/10/2023 | H53: 27/10/2023 | I53: 25/10/2023 | M53: THẩm định sizing Camera JF bổ sung tài nguyên
...

Sheet Cấp phát TN
C1: Ghi chú : - Khi có tiến độ mới thì xuống dòng ghi chữ [New] ở đầu dòng mới để lãnh đạo nắm được - Đầu mối đơn vị ghi tên mail và đơn vị yêu cầu - Khi xong thì đánh dấu x vào cột Hoàn Thành để lãnh đạo nắm được
A2: STT | B2: Mã PYC | C2: Dự án | D2: Đơn vị | E2: Đầu mối y/c | F2: Đầu mối P.HT | G2: Mã SR | H2: Tiến độ, vướng mắc, đề xuất | I2: Thời gian tiếp nhận y/c | J2: Timeline thực hiện theo GNOC | K2: Thời gian hoàn thành | L2: Hoàn thành
A3: 1 | C3: Jira | D3: BSS | F3: hieuhv13 | G3: SR_VN_20230130_729328/ SR_VN_20230312_752885 | J3: KTTC:30/1-6/2 (Thẩm định xong đúng hạn) Ngày pending: 6/2-28/2 VHKT: 8/3-16/3 | L3: x
A4: 2 | C4: C360 | D4: DAC | F4: hieuhv13 | G4: SR_VN_20230405_767360(thu hồi)/ SR_VN_20230405_767368(cấp phát) | L4: x
A5: 3 | C5: Cấp phát tài nguyên dự án QLHS vật lý 3DB Maria | D5: #N/A | F5: hieuhv13 | G5: Đã trao đổi với chaulm5 | H5: A Haipn yc bỏ do đã cắt chuyển chung với DB dự án khác | L5: x
A6: 4 | C6: Cấp phát tài nguyên dự án vật lý CCAI | D6: DAC | E6: dungha7 | F6: hieuhv13 | G6: Đã lập luồng mail với chaulm5 | H6: Đã cấp phát xong | L6: x
A7: 5 | C7: Điều chỉnh tài nguyên Survey 2.0 | D7: BSS | F7: hieuhv13 | G7: SR_VN_20230419_775285 SR_VN_20230425_779549 | H7: 2Các svr cơ bản là đã xong chỉ có 2 DB bị thiếu dung lượng do đã hết khả năng nâng cấp. tuyenpv9 đã thống nhất tạm thời sử dụng như vậy. | J7: KTTC:19/4/2023-26/4/2023 VHKT: 25/4/2023-09/5/2023 | L7: x
A8: 6 | C8: Thu hồi tài nguyên Survey 2.0 | D8: BSS | F8: hieuhv13 | G8: SR_VN_20230426_780377 | J8: KTTC:26/04/2023-08/05/2023 | L8: x
A9: 7 | C9: Cấp phát tài nguyên CCAI | D9: DAC | F9: hieuhv13 | G9: SR_VN_20230419_775606 | H9: Đã hoàn thành | L9: x
A10: 8 | C10: Cấp phát tài nguyên cho MBS | D10: BSS | F10: vinhtq18 | G10: SR_VN_20230480_776480 | J10: KTTC:20/4/2023-27/4/2023 | L10: x
A11: 9 | C11: Thu hồi tài nguyên chuẩn bị cho điều chuyển HT Campaign | D11: BSS | E11: Phund2 | F11: Hoangld2 | G11: KTTC: SR_VN_20230509_786705 VHKT: SR_VN_20230509_786749 | J11: VHKT: 9/5/2023-16/5/2023 | L11: x
A12: 10 | C12: Bổ sung tài nguyên cho hệ thống data3G | D12: VTN | E12: sonnh30 | G12: KTTC: SR_VN_20230320_756800 | H12: Đội dự án cần cấp thêm 4 server qua link LB nhưng hệ thống mới của VTN chưa xong, hiện đang lỗi tủ đĩa chờ part để thay thế, dự kiến cuối tháng 6 mới hoàn thành sonnh30_PUDCNTT-TTVHKTTC-VTN | L12: ẩn | M12: Theo dõi, k tham gia trực tiếp
A13: 11 | C13: Dự án C06 BCA | D13: #N/A | E13: thangnx5 | H13: Đã review xong hồ sơ kt và báo giá gửi cho ttgp cntt | L13: ẩn | M13: Theo dõi, k tham gia trực tiếp
A14: 12 | C14: Hệ thống CMP thương mại | D14: #N/A | E14: quyln3 | H14: A Haipn đã hướng dẫn đơn vị các thủ tục cần làm trước khi được cấp tài nguyên | L14: ẩn | M14: ko có trong file cấp phát
A15: 13 | C15: APIGW | D15: DAC | E15: anhnt576 | F15: Hoangld2 | G15: KTTC: SR_VN_20230705_826658 VHKT: SR_VN_20230710_830025 | H15: đã cấp xong | L15: x
A16: 14 | C16: Bổ sung disk dự án HDDT | D16: BSS | E16: hainv71 | F16: hieuhv13 | G16: SR_VN_20230630_823903 | H16: Đã hoàn thành | J16: 30/06/2023 17:34:00-11/07/2023 17:34:00 | L16: x
A17: 15 | C17: Bổ sung storage mOffice | D17: #N/A | E17: trangttt31 | F17: hieuhv13 | H17: Đã hoàn thành | L17: x | M17: ko có trong file cấp phát
A18: 16 | C18: Hệ thống TMS VHT | D18: BSS | E18: tiendd tuanna29 | F18: hieuhv13 | G18: VHKT: SR_VN_20230711_831000 | H18: Đã cấp xong | J18: 11/07-20/07/2023 | L18: x | M18: lấy của dự án NMS wifi, k có trong file cấp phát
A19: 17 | C19: Voice brand name | D19: BSS | E19: tuyenpv9 | F19: Hoangld2 | G19: SR_VN_20230602_803532 | H19: Đã hoàn thành | J19: KTTC: 2/6-9/6 | L19: x
A20: 18 | C20: Hợp đồng điện tử | D20: BSS | E20: dattht | F20: Hoangld2 | G20: SR_VN_20230623_818696 | H20: Đã hoàn thành | L20: x
A21: 19 | C21: Hợp đồng điện tử nội bộ | D21: BSS | E21: dattht | F21: Hoangld2 | G21: KTTC: SR_VN_20230626_841238 | H21: Đã cấp phát xong | J21: KTTC: 26/7-2/8 VHKT: 3/8-9/8 | L21: x
A22: 20 | C22: Cấp UCTT DCB_DB cho TT VAS | D22: VAS | E22: hanq1 | F22: Hoangld2 | H22: Không thấy A Hanq làm sizing nên tạm đóng lại | L22: x | M22: ko có trong file cấp phát
A23: 21 | C23: Cấp bổ sung dung lượng Vtracking 1.2 | D23: BSS | E23: tuandm2 | F23: Hoangld2 | G23: KTTC: SR_VN_20230717_834515 | H23: Đã cấp xong | J23: KTTC:17/7-24/7 | L23: x | M23: ko có trong file cấp phát
A24: 22 | C24: HT quản lý hồ sơ CT Trái tim cho e | D24: BSS | E24: cuongbm,dattht | F24: vinhtq18 | G24: SR_VN_20230809_854573 | H24: Đã cấp phát xong | J24: KTTC:14/08-21/08/2023 | L24: x | M24: ko có trong file cấp phát
A25: 23 | C25: Tổng hợp nhu cầu cho phần ghi log tập trung | D25: #N/A | E25: namdx;thuynt105 | F25: vinhtq18 | H25: dừng, Hoalh1 thông báo PHT không cần phải tham gia kế hoạch nữa | L25: x | M25: ko có trong file cấp phát
A26: 24 | C26: Cấp phát tài nguyên NAS dự án HDDT | D26: BSS | E26: hainv71 | F26: hieuhv13 | G26: SR_VN_20230620_815799 | H26: Đã hoàn thành | L26: x
A27: 25 | C27: Cấp phát 5 server dự án HDDT | D27: BSS | E27: hainv71 | F27: hieuhv13 | H27: Hủy do chuyển đổi phương án | L27: x
A28: 26 | C28: Cấp phát tài nguyên DB hệ thống nhạc chờ quảng cáo phục vụ giao ban VTN | D28: BSS | E28: hanq1 | F28: ductn | H28: Đã cấp phát xong | L28: x | M28: ko có trong file cấp phát
A29: 27 | C29: Bổ sung tài nguyên cho hệ thống data3G-lần 2 | D29: BSS | F29: None | G29: SR_VN_20230705_826839 | H29: đã cấp xong | J29: KTTC:5/7-14/7 | L29: x
A30: 28 | C30: Cấp phát tài nguyên cho Vtracking 2.0 | D30: BSS | E30: ducdm25 | F30: ductn | G30: SR_VN_20230802_846756 | H30: Đã cấp phát xong | J30: KTTC:2/8-8/8 | L30: x | M30: ko có trong file cấp phát
A31: 29 | C31: Cấp phát tài nguyên cho USSD199 chuyển đổi CSDL mã nguồn mở | D31: BSS | E31: quanhh3 | F31: ductn | G31: SR_VN_20230821_859805 SR_VN_20230823_862290 | H31: Đã cấp phát xong | J31: KTTC:23-31/08/2023 | L31: x
A32: 30 | C32: Thu hồi tài nguyên hệ thống nhạc chờ quảng cáo | D32: VAS | E32: hanq1 | F32: ductn | G32: SR_VN_20230801_845766 | H32: Đã thu hồi xong | J32: KTTC:2/8-8/8 | L32: x
A33: 31 | C33: Cấp phát tài nguyên hệ thống nhạc chờ quảng cáo | D33: VAS | E33: hanq1 | F33: ductn | G33: SR_VN_20230801_845806 | H33: Đã cấp phát xong | J33: KTTC:2/8-8/8 | L33: x
A34: 32 | C34: Thu hồi phân vùng /backup DB HDDT 2.0 | D34: BSS | E34: hainv71 | F34: hieuhv13 | G34: SR_VN_20230721_838316 | H34: Đã thu hồi xong | L34: x
A35: 33 | C35: Bổ sung RAM, backup, logs, u01 DB HDDT 2.0 | D35: BSS | E35: hainv71 | F35: hieuhv13 | G35: SR_VN_20230721_838319 SR_VN_20230804_848646 SR_VN_20230822_860821 | H35: Cần dồn dịch tài nguyên nên cần thu hồi và cấp phát lại các VM Đang đẩy SR thu hồi sang VHKT. Còn 1 svr chưa move xong hạ tầng và 9 svr chưa nâng ram | J35: Do VHKT và KTTC chưa thống nhất được với nhau nên tạm ko cập nhật | L35: x
A36: 34 | C36: Bổ sung Disk DB truyền nhận HDDT | D36: BSS | E36: hainv71 | F36: hieuhv13 | G36: SR_VN_20230721_838308 SR_VN_20230804_848646 SR_VN_20230822_860821 | H36: Cần dồn dịch tài nguyên nên cần thu hồi và cấp phát lại các VM Đang đẩy SR thu hồi sang VHKT. Còn 1 svr chưa move xong hạ tầng và 9 svr chưa nâng ram | J36: Do VHKT và KTTC chưa thống nhất được với nhau nên tạm ko cập nhật | L36: x
A37: 35 | C37: Thu hồi phân vùng /backup DB truyen nhan HDDT 2.0 | D37: BSS | E37: hainv71 | F37: hieuhv13 | G37: SR_VN_20230721_838393 SR_VN_20230728_842829 | H37: Đã thu hồi xong | L37: x
A38: 36 | C38: ARPU dagoras | D38: BSS | E38: anhnt576 | F38: vinhtq18 | G38: SR_VN_20230731_843633 | H38: Đã cấp phát xong | J38: KTTC:31/07/2023-07/08/2023 | L38: x
A39: 37 | C39: Cấp phát 10 server cho Imuzik dồn dịch sang VTT private cloud | D39: VAS | E39: nhatnt2 | F39: ductn | G39: SR_VN_20230825_863935 SR_VN_20230824_863188 | H39: Đã cấp phát xong | J39: Cấp phát theo luồng nBox | L39: x
A40: 38 | C40: Cấp phát tài nguyên server FTP cho hệ thống IBM | D40: BSS | E40: dinhvv | F40: vinhtq18 | G40: SR_VN_20230830_867755 | H40: Đã cấp phát xong | J40: KTTC:30/08-08/09/2023 | L40: x
...

Sheet Chi tiết
A1: STT | B1: Dự án | C1: Đơn vị | D1: Đầu mối y/c | E1: Đầu mối P.HT | F1: Mã SR | G1: Quý cấp phát | H1: Số lượng máy chủ | I1: vCPU | J1: Cint | K1: RAM (GB) | L1: SAN (GB) | M1: NAS (GB) | N1: Ceph (GB) | O1: Bigdata (GB) | P1: Archiving (GB) | Q1: S3 Object (GB) | R1: Pool/Nguồn tài nguyên | S1: Nhóm tài nguyên | T1: Ghi chú
A2: 1 | B2: Login_Fail | H2: 3 | I2: 72 | J2: =I2*3 -> 216 | K2: 72 | L2: 23380 | R2: Private Cloud | S2: pc2021 | T2: haipn hiệu chỉnh số liệu
A3: 2 | B3: VCGW | C3: VAS | H3: 3 | I3: 36 | J3: =I3*3 -> 108 | K3: 48 | L3: 1380 | R3: Private Cloud | S3: pc2021 | T3: haipn hiệu chỉnh số liệu
A4: 3 | B4: GSCG-CSKH | C4: DAC | H4: 16 | I4: 716 | J4: =I4*3 -> 2148 | K4: 1024 | L4: 33960 | M4: 21800 | R4: Private Cloud | S4: pc2021 | T4: haipn hiệu chỉnh số liệu
A5: 4 | B5: Callbot Inbound | C5: DAC | H5: 25 | I5: 932 | J5: =I5*3 -> 2796 | K5: 1600 | L5: 51450 | M5: 36800 | R5: Private Cloud | S5: pc2021
A6: 5 | B6: Digidata | C6: BSS | H6: 10 | I6: 120 | J6: =I6*3 -> 360 | K6: 416 | L6: 7900 | R6: Private Cloud | S6: pc2021
A7: 6 | B7: VDA | C7: VAS | H7: 20 | I7: 304 | J7: =I7*3 -> 912 | K7: 848 | L7: 20300 | R7: Private Cloud | S7: pc2021 | T7: pc2021 và pc2023
A8: 7 | B8: VSGW | C8: VAS | H8: 2 | I8: 40 | J8: =I8*3 -> 120 | K8: 32 | L8: 1120 | R8: Private Cloud | S8: pc2021 | T8: haipn hiệu chỉnh số liệu
A9: 8 | B9: SonarQube | C9: BSS | H9: 6 | I9: 126 | J9: =I9*3 -> 378 | K9: 168 | L9: 2660 | R9: Private Cloud | S9: pc2021
A10: 9 | B10: VDA lần 2 | C10: VAS | H10: 40 | I10: 416 | J10: =I10*3 -> 1248 | K10: 1696 | L10: 35300 | R10: Private Cloud | S10: pc2023
A11: 10 | B11: Payment 2.0 | C11: BSS | F11: SR_VN_20220519_580015 | H11: 2 | I11: 40 | J11: =I11*3 -> 120 | K11: 192 | L11: 1120 | R11: Private Cloud | S11: pc2021
A12: 11 | B12: MyCC (VTS) | C12: ĐHBH | D12: phuongphuong | H12: 35 | I12: 1118 | J12: =I12*3 -> 3354 | K12: 1462 | L12: 12890 | M12: 5000 | R12: Private Cloud | S12: pc2021 | T12: chuyển đầu mối về quynhntp@viettel.com.vn
A13: 12 | B13: VRBT | C13: VAS | F13: SR_VN_20220726_615748 | H13: 12 | I13: 208 | J13: =I13*3 -> 624 | K13: 384 | L13: 9920 | M13: 3400 | R13: Private Cloud | S13: pc2021
A14: 13 | B14: Imuzik | C14: BSS | H14: 51 | I14: 744 | J14: =I14*3 -> 2232 | K14: 1936 | L14: 30240 | R14: Private Cloud | S14: pc2021
A15: 14 | B15: mCC | C15: BSS | H15: 4 | I15: 58 | J15: =I15*3 -> 174 | K15: 256 | L15: 1640 | R15: Private Cloud | S15: pc2021
A16: 15 | B16: CSDL Quốc gia | C16: BSS | F16: SR_VN_20220421_567639 | H16: 2 | I16: 64 | J16: =I16*3 -> 192 | K16: 192 | L16: 2220 | R16: Private Cloud | S16: pc2021
A17: 16 | B17: vESS | C17: TTSP | F17: SR_VN_20220211_538486 | G17: Q1/2022 | H17: 33 | I17: 500 | J17: =I17*3 -> 1500 | K17: 1976 | L17: 37650 | R17: Private Cloud | S17: pc2021
A18: 17 | B18: ObserveIT | C18: ATTT | F18: SR_VN_20220228_543700 | G18: Q1/2022 | H18: 2 | I18: 48 | J18: =I18*3 -> 144 | K18: 64 | L18: 11420 | R18: Cloud HLC | S18: san2021
A19: 18 | B19: Nexus CI/CD | C19: SPHT | F19: SR_VN_20220301_544317 | G19: Q1/2022 | H19: 3 | I19: 24 | J19: =I19*3 -> 72 | K19: 48 | L19: 5250 | R19: Cloud HLC | S19: san2021
A20: 19 | B20: VCGW | C20: VAS | F20: SR_VN_20220303_545482 | G20: Q1/2022 | H20: 2 | I20: 50 | J20: =I20*3 -> 150 | K20: 80 | L20: 2200 | R20: Cloud HLC | S20: san2021
A21: 20 | B21: Bố sung dung lưọng DB truyền dẫn HĐDT | C21: BSS | F21: SR_VN_20220310_548839 | G21: Q1/2022 | H21: nâng cấp | J21: =I21*3 -> 0 | K21: 96 | L21: 3600 | R21: Cloud HLC | S21: san2020
A22: 21 | B22: Nhà Nông Xanh | C22: VAS | F22: SR_VN_20220602_586144 | G22: Q1/2022 | H22: 19 | I22: 232 | J22: =I22*3 -> 696 | K22: 192 | N22: 12980 | R22: Cloud HHT | S22: ceph2020
A23: 22 | B23: Scontract | C23: BSS | F23: SR_VN_20210928_467637 | G23: Q1/2022 | H23: 11 | I23: 176 | J23: =I23*3 -> 528 | K23: 360 | N23: 9410 | R23: VTT 2020 | S23: ceph2020
A24: 23 | B24: Bổ sung dung lưọng DB My Viettel | C24: BSS | F24: SR_VN_20220407_562042 | G24: Q2/2022 | H24: nâng cấp | I24: 72 | J24: =I24*3 -> 216 | K24: 288 | L24: 6600 | R24: Cloud HLC | S24: san2021
A25: 24 | B25: Truyền hóa đơn điện tử | C25: BSS | F25: SR_VN_20220603_587186 | G25: Q2/2022 | H25: 19 | I25: =611/3 -> 203.66667 | J25: =I25*3 -> 611 | K25: 4072 | L25: 4699 | R25: VTT 2020 | S25: san2020
A26: 25 | B26: Hóa đơn điện tử 2.0 | C26: BSS | F26: SR_VN_20220127_535611 | G26: Q2/2022 | H26: 8 | I26: =1273/3 -> 424.33333 | J26: =I26*3 -> 1273 | K26: 474 | L26: 3261 | R26: Cloud HLC | S26: san2020
A27: 26 | B27: Websecurity | C27: ATTT | F27: SR_VN_20220223_542435 | G27: Q2/2022 | H27: 8 | I27: 427 | J27: =I27*3 -> 1281 | K27: 1691 | L27: =20000*8 -> 160000 | R27: VTT 2020
A28: 27 | B28: MyViettel | C28: BSS | F28: SR_VN_20220717_611090 | G28: Q2/2022 | H28: 4 | I28: 129 | J28: =I28*3 -> 387 | K28: =90*4 -> 360 | L28: =680*4 -> 2720 | R28: Cloud HLC | S28: san2020
A29: 28 | B29: Cấp phát tài nguyên hệ thống HDĐT GW | C29: BSS | F29: SR_VN_20220530_584894 | G29: Q2/2022 | H29: 20 | I29: 124 | J29: =I29*3 -> 372 | K29: 346 | L29: 2814 | R29: Cloud HLC | S29: san2021
A30: 29 | B30: Cấp phát tài nguyên hệ thống HDĐT Tem vé | C30: BSS | F30: SR_VN_20220603_586882 | G30: Q2/2022 | H30: 111 | I30: 1513 | J30: =I30*3 -> 4539 | K30: =(140+1272)*3 -> 4236 | L30: 105466 | R30: Cloud HLC | S30: san2021
A31: 30 | B31: Nâng cấp truyền nhận HDDT lần 2 | C31: BSS | F31: SR_VN_20220401_559616 | G31: Q2/2022 | H31: nâng cấp | I31: 26 | J31: =I31*3 -> 78 | K31: 72 | L31: 30600 | R31: Cloud HLC | S31: san2020
A32: 31 | B32: Core Game | C32: BSS | F32: SR_VN_20220414_564451 | G32: Q2/2022 | H32: 13 | I32: 56 | J32: =I32*3 -> 168 | K32: 832 | L32: 15600 | R32: Cloud HLC | S32: san2021
A33: 32 | B33: TVBH | C33: BSS | F33: SR_VN_20220316_551065 | G33: Q2/2022 | H33: 13 | I33: 55 | J33: =I33*3 -> 165 | K33: =8*32+3*32+2*16 -> 384 | L33: =8*300+3*300+2*350+800 -> 4800 | R33: Cloud HLC | S33: san2021
A34: 33 | B34: DB TVBH | C34: BSS | F34: SR_VN_20220613_592188 | G34: Q2/2022 | H34: 6 | I34: 60 | J34: =I34*3 -> 180 | K34: =3*32+3*48 -> 240 | L34: =4*4531+4*10354 -> 59540 | R34: Cloud HLC | S34: san2021
A35: 34 | B35: BlockChain | C35: SPHT | F35: SR_VN_20220621_596260 | G35: Q2/2022 | H35: 2 | I35: 10 | J35: =I35*3 -> 30 | K35: 128 | N35: 750 | R35: Cloud HHT | S35: ceph2020
A36: 35 | B36: APIWG | C36: VAS | F36: SR_VN_20220325_556097 | G36: Q2/2022 | H36: 2 | I36: 24 | J36: =I36*3 -> 72 | K36: 434 | L36: 1200 | R36: Cloud HLC | S36: san2020
A37: 37 | B37: Imuzik nhạc chờ | C37: VAS | F37: SR_VN_20220414_564715 | G37: Q2/2022 | H37: 49 | I37: 696 | J37: =I37*3 -> 2088 | K37: 1840 | L37: 27140 | R37: Cloud HLC | S37: san2021
A38: 38 | B38: Vtracking Kafka | C38: BSS | F38: SR_VN_20220707_606245 | G38: Q3/2022 | H38: 4 | I38: =22*4 -> 88 | J38: =I38*3 -> 264 | K38: =44+45+46+47 -> 182 | L38: =4*(537+100) -> 2548 | R38: Cloud HLC | S38: san2020
A39: 39 | B39: BCCS_SALE | C39: BSS | F39: SR_VN_20220725_615131 | G39: Q3/2022 | H39: 10 | I39: 20 | J39: =I39*3 -> 60 | K39: 640 | L39: 3000 | R39: Cloud HLC | S39: san2021
A40: 40 | B40: Nhận diện hình ảnh mBCCS | C40: BSS | F40: SR_VN_20220809_624585 | G40: Q3/2022 | H40: 19 | I40: =46*19 -> 874 | J40: =I40*3 -> 2622 | K40: =64*19 -> 1216 | L40: =120*19 -> 2280 | R40: Cloud HLC | S40: san2021
...

Sheet Tài nguyên Cloud 
A1: Tài nguyên QHĐC 2020
B2: Hiên trạng tài nguyên còn dư | K2: Ghi chú
B3: vCPU | D3: RAM (TB) | F3: CEPH (GB) | G3: SAN (GB) | H3: NAS (GB)
B4: Com_Ceph | C4: Com_SAN | D4: Com_Ceph | E4: Com_SAN
A5: TN còn lại sau KH Q4 | B5: 5383.8 | C5: -4064.5714 | D5: 8815 | E5: 4065 | F5: -40790 | G5: 10332 | H5: -33800
A6: TN trong KH Q4 | B6: 1470 | C6: 1984.5714 | D6: 4.453 | E6: 5204 | F6: 84910 | G6: 131925 | H6: 8000
A7: TN đã sử dụng trong Q4 | B7: 831 | C7: 808.57143 | D7: 3459 | E7: 2546 | F7: 19400 | G7: 100291 | H7: 4000
A8: TN còn lại 2021 | B8: 6022.8 | C8: -2888.5714 | D8: 5360.453 | E8: 6723 | F8: 24720 | G8: 41966 | H8: -29800
A9: Sử dụng 2022 | B9: ='Chi tiết'!$I$259 -> 418 | C9: ='Chi tiết'!$I$260 -> 820 | D9: ='Chi tiết'!$K$259 -> 680 | E9: ='Chi tiết'!$K$260 -> 5776 | F9: ='Chi tiết'!N259 -> 23140 | G9: ='Chi tiết'!$L$260 -> 46618
A10: TN còn lại | B10: =B8-B9 -> 5604.8 | C10: =C8-C9 -> -3708.5714 | D10: =D8-D9 -> 4680.453 | E10: =E8-E9 -> 947 | F10: =F8-F9 -> 1580 | G10: =G8-G9 -> -4652 | H10: =H8-H9 -> -29800
A11: Private Cloud
B12: Hiên trạng tài nguyên còn dư | K12: Ghi chú
B13: vCPU | D13: RAM (GB) | F13: CEPH (GB) | G13: SAN (GB) | H13: NAS (GB) | I13: NAS (theo đầu mối VHKT gửi tháng 3 2025)
B14: Com_Ceph | C14: Com_SAN | D14: Com_Ceph | E14: Com_SAN
A15: Tổng TN 2021 | C15: =3264*4 -> 13056 | E15: =32*384-40 -> 12248 | G15: =612000*0.9 -> 550800 | H15: =125000*0.9 -> 112500 | I15: 109 | K15: vCPU overcomit 1:4
A16: Đã cấp phát 2021 | C16: ='Chi tiết'!$I$265 -> 4490 | E16: ='Chi tiết'!$K$265 -> 7829 | G16: ='Chi tiết'!$L$265 -> 287409 | H16: ='Chi tiết'!M265 -> 105300 | I16: 65.82
A17: TN còn lại 2021 | C17: =C15-C16 -> 8566 | E17: =E15-E16 -> 4419 | G17: =G15-G16 -> 263391 | H17: =H15-H16 -> 7200 | I17: =I15-I16 -> 43.18
A18: Tổng TN 2023 | C18: =4608*4 -> 18432 | E18: 14761 | G18: =175*2*1024*0.9 -> 322560 | H18: =50*1024*0.9 -> 46080 | I18: 50
A19: Đã cấp phát 2023 | C19: ='Chi tiết'!$I$266 -> 4979 | E19: ='Chi tiết'!$K$266 -> 12363 | G19: ='Chi tiết'!$L$266 -> 305419 | H19: ='Chi tiết'!$M$266 -> 18477 | I19: 37.96
A20: TN còn lại 2023 | C20: =C18-C19 -> 13453 | E20: =E18-E19 -> 2398 | G20: =G18-G19 -> 17141 | H20: =H18-H19 -> 27603 | I20: =I18-I19 -> 12.04
A21: Tài nguyên QHĐC 2021
B22: Hiên trạng tài nguyên còn dư | K22: Ghi chú
B23: vCPU | D23: RAM (GB) | F23: CEPH (GB) | G23: SAN (GB) | H23: NAS (GB)
B24: Com_Ceph | C24: Com_SAN | D24: Com_Ceph | E24: Com_SAN
A25: Tổng TN | B25: 689 | C25: =25280-B25 -> 24591 | D25: 1984 | E25: =37545-D25 -> 35561 | F25: 34992 | G25: =1052643-F25 -> 1017651 | H25: 106576 | K25: overcomit 1:2 ( sử dụng server 5-2, 5-1 và 6-2 để dựng cloud )
A26: Đã cấp phát | B26: ='Chi tiết'!I261 -> 0 | C26: ='Chi tiết'!$I$262 -> 10330.13 | D26: ='Chi tiết'!K261 -> 0 | E26: ='Chi tiết'!$K$262 -> 32254 | F26: ='Chi tiết'!N261 -> 10834 | G26: ='Chi tiết'!$L$262 -> 1031612 | H26: ='Chi tiết'!M262 -> 144340
A27: TN còn lại | B27: =B25-B26 -> 689 | C27: =C25-C26 -> 14260.87 | D27: =D25-D26 -> 1984 | E27: =E25-E26 -> 3307 | F27: =F25-F26 -> 24158 | G27: =G25-G26 -> -13961 | H27: =H25-H26 -> -37764
A28: Tài nguyên QHĐC 2022
A29: Hiên trạng tài nguyên còn dư
B30: Com_Ceph | D30: CEPH (GB) | E30: Com_SAN | G30: SAN (GB) | H30: NAS (GB) | I30: Object (GB) | J30: Com_Bigdata | L30: Bigdata (GB) | M30: Archiving (GB) | N30: Bare_metal
B31: vCPU | C31: RAM | E31: vCPU | F31: RAM | J31: vCPU | K31: RAM | N31: vCPU | O31: RAM
A32: Tổng TN | B32: ='DA2022'!Q6*96*0.9 -> 5184 | C32: ='DA2022'!Q6*384*0.75 -> 17280 | D32: =('DA2022'!E12*80+'DA2022'!E12*22)*1024 -> 1880064 | E32: =('DA2022'!J4+'DA2022'!H4)*96*0.9 -> 36720 | F32: =('DA2022'!H4+'DA2022'!J4)*384*0.75 -> 122400 | G32: =('DA2022'!H15*'DA2022'!I53+'DA2022'!H15*'DA2022'!J53+'DA2022'!I15*'DA2022'!I54+'DA2022'!I15*'DA2022'!J54)*1024 -> 6872064 | H32: ='DA2022'!E17*1024 -> 773314.56 | I32: =5500*1024 -> 5632000 | J32: ='vật lý free'!N27+'vật lý free'!N28 -> 20640 | K32: ='vật lý free'!O27+'vật lý free'!O28 -> 79744 | L32: 1179197.4 | M32: 1100001.3 | N32: =SUM('vật lý free'!N22:N26) -> 20064 | O32: =SUM('vật lý free'!O22:O26) -> 56576
A33: Đã cấp phát | B33: ='Chi tiết'!I263 -> 0 | C33: ='Chi tiết'!K263 -> 0 | D33: ='Chi tiết'!L263 -> 0 | E33: ='Chi tiết'!I264 -> 13974 | F33: ='Chi tiết'!K264 -> 31456.2 | G33: ='Chi tiết'!L264+'Cấp phát vật lý'!T22 -> 1150242 | H33: ='Chi tiết'!M264 -> 238396 | I33: ='Chi tiết'!Q264 -> 20490 | J33: ='vật lý free'!P28+'vật lý free'!P27 -> 0 | K33: ='vật lý free'!Q28+'vật lý free'!Q27 -> 0 | L33: ='Cấp phát vật lý'!T23 -> 0 | M33: ='Cấp phát vật lý'!T24 -> 0 | N33: =SUM('vật lý free'!P22:P26) -> 7104 | O33: =SUM('vật lý free'!Q22:Q26) -> 19456
A34: TN còn lại | B34: =B32-B33 -> 5184 | C34: =C32-C33 -> 17280 | D34: =D32-D33 -> 1880064 | E34: =E32-E33 -> 22746 | F34: =F32-F33 -> 90943.8 | G34: =G32-G33 -> 5721822 | H34: =H32-H33 -> 534918.56 | I34: =I32-I33 -> 5611510 | ... O34: =O32-O33 -> 37120

Sheet vật lý free
A1: Lô tài nguyên | B1: Mã | C1: Loại | D1: CPU | E1: RAM | F1: Disk | G1: Bigdata | H1: Archiving | I1: HBA | J1: GPU | K1: Tổng | L1: Ghi chú | M1: Đã cấp | N1: VTNet cấp phát
A2: 0405 IDC | B2: SV 1 | C2: - 2xXeon Gold 6252 6x64GB RAM 2x600HDD HBA Card RAID 2 NIC | D2: Gold 6252 | E2: 384 | F2: HDD: 2x600GB | I2: Y | K2: 7 | L2: Đang lắp 2 rack cùng hạ tầng Private Cloud
A3: 0405 IDC | B3: SV 2 | C3: - 2xXeon Bronze 3206R RAM: 4x32GB HDD: 2x600GB HBA Card RAID 2 NIC | D3: Bronze 3206R | E3: 128 | F3: HDD: 2x600GB | I3: Y | K3: 3 | L3: Đang lắp 2 rack cùng hạ tầng Private Cloud
A4: 0405 IDC | B4: SV 3 | C4: - 2xXeon Bronze 3206R RAM: 4x32GB HDD1: 2x600GB SAS HDD2: 3x2 TB SATA HDD3: 2x3.84 TB SSD HBA Card RAID 2 NIC | D4: Bronze 3206R | E4: 128 | F4: HDD1: 2x600GB SAS HDD2: 3x2 TB SATA SSD: 2x3.84 TB | I4: Y | K4: 3 | L4: Đang lắp 2 rack cùng hạ tầng Private Cloud
A5: Private cloud | B5: sv node 2 | C5: HPE DL380 Gen10 (CPU: 2 x Xeon Silver 4214R; RAM: 256GB, SSD: 2x480GB, 2 HBA 16Gbps) | D5: Silver 4214R | E5: 256 | F5: SSD: 2x480GB | I5: Y | K5: 4
A6: QHĐC 2020 | B6: SV4-1 | C6: Server HPE Apollo R2600 - | D6: Silver 4214R | E6: 128 | F6: SSD: 2 x 1.92 TB | K6: 1
C7: XL170r Gen10 (2 x Xeon Silver 4214R; RAM: 128GB, SSD: 2 x 1.92 TB)
A8: QHĐC 2020 | B8: SV4-5 | C8: DL360 Gen10 (CPU: 2 x Xeon Silver 4214R; RAM: 256GB, SSD: 2x1.92 TB) | D8: Silver 4214R | E8: 256 | F8: SSD: 2x1.92 TB | K8: 5
A9: QHĐC 2020 | B9: SV 5-1 | C9: DL360 Gen10 (CPU: 2 x Xeon Gold 5218R; RAM: 384GB, SSD: 2x600 GB) | D9: Gold 5218R | E9: 384 | F9: SSD: 2x600 GB | K9: 3
A10: Bigdata 2021 | B10: SV 5-4 | C10: 2x Gold 5318Y, 256GB RAM, SSD: 2 x 960G | D10: Gold 5318Y | E10: 256 | F10: SSD: 2 x 960G | G10: 365,000 | K10: 31 | L10: Quy hoạch cho Campaign (anhdt156) | M10: 31
A11: Bigdata 2021 | B11: SV 5-4 | C11: 2x Gold 5318Y, 256GB RAM, SSD: 2 x 960G | D11: Gold 5318Y | E11: 256 | F11: SSD: 2 x 960G | G11: 627,000 | H11: 1,035,000 | K11: 52 | L11: Quy hoạch Cus360 48, Adhoc 4 (sonln3) | M11: 28 | N11: huyndn cấp 25/6/2024, 4 sv adhoc, 20 sv cus360
A12: Bigdata 2021 | B12: SV 5-4 | C12: 2x Gold 5318Y, 256GB RAM, SSD: 2 x 960G | D12: Gold 5318Y | E12: 256 | F12: SSD: 2 x 960G | G12: 509,800 | K12: 25 | L12: Quy hoạch CCAI 6, Analytic 19 (dungha7) | M12: 25 | N12: huyndn cấp 24/6/2024, 19 sv analytic
A13: Bigdata 2021 | B13: SV 5-4 | C13: 2x Gold 5318Y, 256GB RAM, SSD: 2 x 960G | D13: Gold 5318Y | E13: 256 | F13: SSD: 2 x 960G | G13: 10,240 | K13: 6 | L13: Quy hoạch Billing (dungpt16) | M13: 6 | N13: huyndn cấp 24/6/2024, 6 sv billing
A14: VTM bàn giao 2689/BB-CNTT | B14: SV13 Cloud | C14: PowerEdge R750: 2 x Intel Xeon Silver 4314 2.4G, 4x32GB RAM, 8x3.84TB SSD SAS; 2x600GB SAS | D14: Silver 4314 | E14: 128 | F14: 8x3.84TB SSD SAS; 2x600GB SAS | I14: Y | K14: 15 | L14: Cty Truyền thông Viettel (đầu mối ThườngLX) bàn giao 30 sv cho TT.PTDL theo CV 2689/BB-CNTT ngày 31/7/2023 | M14: 15
A15: VTM bàn giao 2689/BB-CNTT | B15: SV12 Cloud | C15: PowerEdge R750: 2 xIntel Xeon Gold 6326 2.9G, 4x32GB RAM, 2x960GB SSD SAS; 2x600GB SAS, 2xA30 | D15: Gold 6326 | E15: 128 | F15: 2x960GB SSD SAS; 2x600GB SAS | I15: Y | J15: 2xA30 | K15: 15 | L15: Cty Truyền thông Viettel (đầu mối ThườngLX) bàn giao 30 sv cho TT.PTDL theo CV 2689/BB-CNTT ngày 31/7/2023 | M15: 15
A16: ThangTD1 mail 04/07/2024 | C16: PowerEdge R750XA: 2xIntel Xeon Gold 5318S 2.1G, 8x32GB RAM; 2x960GB SSD; 3xNVIDIA Ampere A30 24GB Passive | D16: Gold 5318S | E16: 256 | F16: 2x960GB SSD SAS | J16: 3xA30 | K16: 2 | L16: IP OS: 10.207.163.81/82 IP quản trị: 10.205.63.71/72 | M16: 2 | N16: ChauLM5 báo VTT có 3 sv ở HLC (whatsapp) hieupc3 mail có 2 sv, fw cho trungtd3 dùng
A17: Chaulm5 cấp phát cho TSA | C17: Máy chủ PowerEdge R650 Server: 2 x Intel Xeon Gold 5318Y 2.1G, 24C/48T, 11.2GT/s, 36M Cache, Turbo, HT (165W) DDR4-2933; 8x32GB RDIMM, 3200MT/s, Dual Rank; 2x1.92TB SSD SAS ISE; | D17: Gold 5318Y | E17: =8*32 -> 256 | F17: SSD: 2 x 1.92 TB | K17: 3 | L17: Cấp phát cho hệ thống TSA theo KH tháng 7/2024 | M17: 3
A18: Chaulm5 whatsapp 28/10/2024 | C18: Máy chủ PowerEdge R650 Server: 2 x Intel Xeon Gold 5318Y 2.1G, 24C/48T, 11.2GT/s, 36M Cache, Turbo, HT (165W) DDR4-2933; 4x32GB RDIMM, 3200MT/s, Dual Rank; 2x1.92TB SSD SAS ISE; | D18: Gold 5318Y | E18: 128 | F18: SSD: 2 x 1.92 TB | I18: Y | K18: 6 | L18: Lô 2021, không có quy hoạch dung lượng
A20: Tài nguyên vật lý QHDC 2022
A21: Mã trạm | B21: Loại server | C21: Cấu hình | D21: CPU | E21: RAM | F21: Disk | G21: Bigdata | H21: Archiving | I21: HBA | J21: GPU | K21: Tổng | L21: Ghi chú | M21: Đã cấp | N21: Tổng CPU | O21: Tổng RAM | P21: CPU used | Q21: RAM used
A22: HLC | B22: 1 | C22: Dell R650 2xIntel 5318Y 8x32GB 2x600GB SAS 2x NIC 10G dual port | D22: 96 | E22: 256 | F22: 2x600GB SAS | I22: Y | K22: 68 | L22: cấp phát 1 svr DB roaming | M22: 4 | N22: =K22*D22 -> 6528 | O22: =K22*E22 -> 17408 | P22: =($M22)*D22 -> 384 | Q22: =($M22)*E22 -> 1024
A23: HKH | B23: 1 | C23: Dell R650 2xIntel 5318Y 8x32GB 2x600GB SAS 2x NIC 10G dual port | D23: 96 | E23: 256 | F23: 2x600GB SAS | I23: Y | K23: 101 | L23: Đã cấp 50 svr cho TV360, còn 51 server VTT cầm - thongnv31 | M23: 50 | N23: =K23*D23 -> 9696 | O23: =K23*E23 -> 25856 | P23: =($M23)*D23 -> 4800 | Q23: =($M23)*E23 -> 12800
A24: HKH | B24: 2 | C24: Dell R650 2xIntel 5318Y 8x64GB 2x600GB SAS 2x NIC 10G dual port | D24: 96 | E24: 512 | F24: 2x600GB SAS | I24: Y | K24: 2 | L24: Đã cấp hết cho TV360 | M24: 2 | N24: =K24*D24 -> 192 | O24: =K24*E24 -> 1024 | P24: =($M24)*D24 -> 192 | Q24: =($M24)*E24 -> 1024
A25: HLC | B25: 4 | C25: Dell R6502xIntel 5318Y 4x32GB/4x64GB 2x600GB SAS 2x1,92TB SSD 2x NIC 10G dual port | D25: 96 | E25: 384 | F25: 2x600GB SAS 2x1,92TB SSD | K25: 20 | N25: =K25*D25 -> 1920 | O25: =K25*E25 -> 7680 | P25: =($M25)*D25 -> 0 | Q25: =($M25)*E25 -> 0
A26: HLC | B26: 6 | C26: DELL R750XA 2xIntel 5318S 4x64GB 2x800G SSD 2x1,92TB SSD 1x NIC 10G Quad port | D26: 96 | E26: 256 | F26: 2x800G SSD 2x1,92TB SSD | I26: Y | J26: 3xNVIDIA A30 | K26: 18 | L26: Cấp phát 10 server cho đội DAC (CCAI-dungha7) Cấp phát 8 server cho đội DAC (Callbot, GSCG-Kientt6) | M26: 18 | N26: =K26*D26 -> 1728 | O26: =K26*E26 -> 4608 | P26: =($M26)*D26 -> 1728 | Q26: =($M26)*E26 -> 4608
A27: HKH | B27: Big DATA1 | C27: Dell R650 2xIntel 5318Y 4x64GB 2x1.92TB SSD 2x NIC 10G dual port | D27: 96 | E27: 256 | F27: 2x1.92TB SSD | G27: x | K27: 22 | N27: =K27*D27 -> 2112 | O27: =K27*E27 -> 5632 | P27: =($M27)*D27 -> 0 | Q27: =($M27)*E27 -> 0
A28: HKH | B28: Big DATA2 | C28: Dell R650 2xIntel 5318Y 4x32GB 4x64GB 2x600GB SAS 2x NIC 10G dual port | D28: 96 | E28: 384 | F28: 2x600GB SAS | G28: x | K28: 193 | L28: Tài nguyên cloud loại 1 chuyển sang bigdata - thongnv31 cầm | N28: =K28*D28 -> 18528 | O28: =K28*E28 -> 74112 | P28: =($M28)*D28 -> 0 | Q28: =($M28)*E28 -> 0
A36: Tài nguyên vật lý QHDC 2023
A37: Mã trạm | B37: Loại server | C37: Cấu hình | D37: CPU | E37: RAM | F37: Disk | G37: Bigdata | H37: Archiving | I37: HBA | J37: GPU | K37: Tổng | L37: Ghi chú | M37: Đã cấp
A38: HLC | B38: Vật lý loại 1 | C38: 2xIntel 5318Y 4x32GB, 2x960 GB SSD | E38: 128 | F38: 2x960 GB SSD | K38: 21
A39: HLC | B39: Vật lý loại 2 | C39: 2xIntel 5318Y 4x32GB, 2x960 GB SSD | E39: 128 | F39: 2x960 GB SSD | K39: 19 | L39: Quy hoạch cấp phát DB oracle
A40: HLC | B40: Vật lý loại 3 | C40: 2xIntel 5318Y 4x64GB, 2x960 GB SSD | E40: 256 | F40: 2x960 GB SSD | I40: Y | K40: 2
A41: HLC | B41: Vật lý loại 4 | C41: 2xIntel 5318Y 4x64GB, 2x960 GB SSD | E41: 256 | F41: 2x960 GB SSD | K41: 19 | L41: Quy hoạch cấp phát DB oracle
A42: HLC | B42: Vật lý loại 5 | C42: 2xIntel 5318Y 4x64GB, 2x960 GB SSD, 3x10TB HDD | E42: 256 | F42: 2x960 GB SSD 3x10TB HDD | I42: Y | K42: 120
A43: HLC | B43: Vật lý loại 7 | C43: 2xIntel 5318Y 384GB, 2x960 GB SSD | E43: 384 | F43: 2x960 GB SSD | K43: 5
A44: HLC | B44: GPU loại 1 | C44: 2xIntel Xeon Gold 5418Y 4x64GB 2x1.96 TB SSD | D44: 192 | E44: 256 | F44: 2x1.92 TB SSD | I44: Y | J44: NVIDIA L4 | K44: 12 | L44: Kientt6: 12 sv loại 1 + 8 sv loại 3 Dungha7: 11 sv loại 2 + 5 sv loại 3 | M44: 12
A45: HLC | B45: GPU loại 2 | C45: 2xAMD AMD EPYC 9554 4x64GB, 2x1.92B; 2x3.84 GB SSD | D45: 256 | E45: 256 | F45: 2x1.92 TB SSD 2x3.84 TB SSD | I45: Y | J45: NVIDIA L4 | K45: 11 | L45: Kientt6: 12 sv loại 1 + 8 sv loại 3 Dungha7: 11 sv loại 2 + 5 sv loại 3 | M45: 11
A46: HLC | B46: GPU loại 3 | C46: 2xIntel Xeon Gold 5418Y 384 GB 2x960 GB SSD | D46: =96*2 -> 192 | E46: 384 | F46: 2x1.92 TB SSD | I46: Y | J46: NVIDIA L40 | K46: 13 | L46: Kientt6: 12 sv loại 1 + 8 sv loại 3 Dungha7: 11 sv loại 2 + 5 sv loại 3 | M46: 13
B47: Vật lý loại 3 | C47: Dell PowerEdge R660 2 xIntel Xeon-Gold 5418Y 4x64GB DDR5 2x960GB SSD 3x8TB SAS" | E47: 256 | F47: 2x960 GB SSD 3x8TB SAS | G47: 7,3PB | I47: Y | K47: 215 | L47: 7,3PB lưu trữ datalake => TK ở HLA
B48: Vật lý loại 5 | C48: Dell PowerEdge R760 2xIntel Xeon-Gold 5418Y 4x64GB DDR5 "2x960GB SSD | E48: 256 | F48: 2x960 GB SSD 3x8TB SAS | G48: 7,3PB | K48: 9 | L48: 7,3PB lưu trữ datalake => TK ở HLA
...

Sheet Cấp phát vật lý
A1: STT | B1: Dự án | C1: Đơn vị | D1: Đầu mối | E1: Đầu mối p.HT | F1: Ngày cấp | G1: Quý cấp phát | H1: Số lượng máy chủ | I1: vCPU | J1: Cint | K1: RAM | L1: SAN | M1: NAS | N1: Ceph | O1: Bigdata | P1: Archiving | Q1: Pool/Nguồn tài nguyên | R1: Phân loại nhóm tài nguyên | S1: Ghi chú
A2: 1 | B2: QLHS | C2: BSS | H2: 3 | L2: =(8.5*1024+200+5*1024+60+(8.5*1024+200+60)*2) -> 32012 | Q2: Vật lí 2021 | R2: 2021 | S2: Sv5-22
A3: 2 | B3: AI nhận diện (Bộ CA) | C3: BSS | D3: phund2 | F3: 25/11/2022 | G3: Q4/2022 | H3: 30 | I3: =80*H3 -> 2400 | J3: =I3*3 -> 7200 | K3: =256*H3 -> 7680 | S3: VTNet ko thu hồi sv mượn nữa (từ 2022), hoàn trả bằng QHĐC 2022. 02xIntel Xeon Gold 5218r, 256GB RAM, 2x600 SAS
A4: 3 | B4: IPCC HNI - DR | C4: DVKH | D4: trongtd1 | F4: 26/9/2023 | G4: Q3/2023 | H4: 2 | I4: =96*H4 -> 192 | J4: =I4*3 -> 576 | K4: =8*32*H4 -> 512 | Q4: chaulm5 | S4: PowerEdge R650 Server: 2 x Intel Xeon Gold 5318Y 2.1G, 24C/48T, DDR4 8x32GB, 2x600GB Hard Drive SAS, Dual Port 16Gb Fibre Channel HBA (serial: 3Z822S3, GCYYRR3)
A5: 4 | B5: CCAI | C5: DAC | D5: dungha7 | F5: 23/2/2024 | G5: Q1/2024 | H5: 6 | I5: 201 | J5: 660 | K5: =256*H5 -> 1536 | O5: 150000 | Q5: Vật lí 2021 | R5: 2021 | S5: Sv5-4 (2x Gold 5318Y, 256GB RAM, SSD: 2 x 960G)
A6: 5 | B6: Campaign management | C6: BSS | D6: anhdt156 | F6: 45446 | G6: Q1/2024 | H6: 31 | I6: 903 | J6: 2710 | K6: 7936 | O6: 372736 | Q6: Vật lí 2021 | R6: 2021 | S6: 2x Gold 5318Y, 256GB RAM, SSD: 2 x 960G
A7: 6 | B7: Database V-Tracking 2023 | C7: BSS | D7: tramdtt1 | G7: Q1/2024 | H7: 2 | I7: 8 | J7: 24 | K7: 64 | L7: 1326 | S7: Cấp tài nguyên Database, Yêu cầu cấp hạ tầng vật lí Database cùng tổng trạm với server App (10.60.32.175, 10.60.32.176 - Hòa Lạc) Cụ thể: Bổ sung cụ thể từng phân vùng như sau: Storage : 1326 GB Cụ thể từng phân vùng như sau: CRS: 15G ARC: 500G REDO 1 50G REDO 2 50G DATA: Số dung lượng còn lại
A8: 7 | B8: Cloud CA | C8: BSS | D8: thanhtt69 | G8: Q2/2024 | H8: 8 | I8: 355 | J8: 1063 | K8: 1599 | L8: 28215 | Q8: chaulm5
A9: 8 | B9: VTT Analytic | C9: DAC | D9: dungha7 | G9: Q2/2024 | H9: 30 | I9: 1830 | J9: 5490 | K9: =128*15+128*15 -> 3840 | O9: 528600 | Q9: Vật lý 2021 | S9: VTM bàn giao: 2689/BB-CNTT PowerEdge R750: 2 x Intel Xeon Silver 4314 2.4G, 4x32GB RAM, 8x3.84TB SSD SAS; 2x600GB SAS PowerEdge R750: 2 xIntel Xeon Gold 6326 2.9G, 4x32GB RAM, 2x960GB SSD SAS; 2x600GB SAS, 2xA30
A10: 9 | B10: TSA | C10: BSS | D10: Dungdb1 | G10: Q3/2024 | H10: 3 | I10: =3*2*24 -> 144 | J10: =I10*3 -> 432 | K10: =3*8*32 -> 768 | L10: =3*2*19200 -> 115200 | Q10: chaulm5 | S10: 3 x Máy chủ PowerEdge R650 Server: 2 x Intel Xeon Gold 5318Y 2.1G, 24C/48T, 11.2GT/s, 36M Cache, Turbo, HT (165W) DDR4-2933; 8x32GB RDIMM, 3200MT/s, Dual Rank; 2x1.92TB SSD SAS ISE;
A11: Tài nguyên vật lý 2022
A12: 1 | B12: DB roaming hạn 12 tháng | C12: ĐS | D12: anhnt162 | E12: vinhtq18 | G12: Q4/2024 | H12: 1 | I12: 32 | J12: 96 | K12: 96 | L12: 8192 | Q12: HLC Vat ly loai 1 | R12: 2022 | S12: 1 x máy chủ Dell R650 2xIntel 5318Y 8x32GB 2x600GB SAS 2x NIC 10G dual port
A13: 2 | B13: PBH 3.0 | C13: BSS | D13: thanhdv125 | E13: thongnv31 | G13: Q4/2024 | H13: 3 | I13: 278 | J13: 834 | K13: 768 | L13: 43300 | Q13: HLC Vat ly loai 1 | R13: 2022 | S13: 3 x máy chủ Dell R650 2xIntel 5318Y 8x32GB 2x600GB SAS 2x NIC 10G dual port
U22: San2022 | V22: =SUMIF($R$2:$R$217,"=2022",L2:L217) -> 51492
U23: bigdata2022 | V23: =SUMIF($R$2:$R$217,"=2022",O3:O218) -> 0
U24: Archiving2022 | V24: =SUMIF($R$2:$R$217,"=2022",P3:P218) -> 0

Sheet MyCC
A1: STT | B1: Cloud | C1: Tên dự án | D1: Service | E1: Hostname | F1: IP | H1: Loại OS | I1: Cấu hình phần cứng | K1: Dung lượng ổ cứng | N1: Tài nguyên cấp phát | P1: Network Limit | Q1: Gateway | R1: VHKT | S1: Owner server | T1: Route | U1: Package | V1: Monitored Prometheus | W1: Ghi chú
F2: DCN | G2: IP Khác | I2: vCPU | J2: RAM | K2: Volume OS (GB) | L2: Volume khác (GB) | M2: NAS | N2: HA | O2: Storage Pool
A3: 1 | B3: Cloud_VTT | C3: MyCC | D3: appipccx | E3: mycc-appipccx-10205058089 | F3: 10.205.58.89/24 | G3: 10.207.189.5/24 10.52.125.6/24 171.229.16.33/24 | H3: CentOS_7_7_final | I3: 14 | J3: 54 | K3: 60 | L3: u01: 190 | N3: VTT_SAN_2021_Q4_01 | O3: IDC7F_E07_Unity_880_1020502474_SAS | P3: 1 | Q3: 10.207.189.254 | R3: Yes | S3: anhtt69 | T3: 10.240.201.49/32 via 10.205.58.254 dev eth0 10.254.139.0/24 via 10.205.58.254 dev eth0 10.240.226.0/24 via 10.205.58.254 dev eth0 10.255.58.0/24 via 10.205.58.254 dev eth0 10.60.101.0/24 via 10.205.58.254 dev eth0 10.58.15.114/32 via 10.205.58.254 dev eth0 10.58.137.0/24 via 10.205.58.254 dev eth0 10.60.7.0/24 via 10.205.58.254 dev eth0 10.60.97.0/24 via 10.205.58.254 dev eth0 192.168.182.8/32 via 10.205.58.254 dev eth0 10.60.96.0/24 via 10.205.58.254 dev eth0 10.58.4.0/24 via 10.205.58.254 dev eth0 10.58.65.0/24 via 10.205.58.254 dev eth0 10.40.17.0/24 via 10.205.58.254 dev eth0 10.74.225.0/24 via 10.205.58.254 dev eth0 10.60.131.0/24 via 10.205.58.254 dev eth0 10.60.129.0/24 via 10.205.58.254 dev eth0 10.30.160.0/24 via 10.205.58.254 dev eth0 10.61.151.0/24 via 10.205.58.254 dev eth0 10.60.100.0/24 via 10.205.58.254 dev eth0 192.168.176.0/24 via 10.205.58.254 dev eth0 192.168.252.0/24 via 10.205.58.254 dev eth0 192.168.131.50/32 via 10.205.58.254 dev eth0 10.240.178.0/24 via 10.205.58.254 dev eth0 10.240.166.2/32 via 10.205.58.254 dev eth0 10.240.188.0/24 via 10.205.58.254 dev eth0 10.240.202.0/24 via 10.205.58.254 dev eth0 10.60.100.73/32 via 10.205.58.254 dev eth0 10.60.5.133/32 via 10.205.58.254 dev eth0 | V3: Yes | W3: Dau moi dich vu: tannph | X3: Các server đã cấp nhưng chưa dùng
A4: 2 | B4: Cloud_VTT | C4: MyCC | D4: appipccx | E4: mycc-appipccx-10205058090 | F4: 10.205.58.90/24 | G4: 10.207.189.6/24 10.52.125.7/24 171.229.16.34/24 | H4: CentOS_7_7_final | I4: 14 | J4: 54 | K4: 60 | L4: u01: 190 | N4: VTT_SAN_2021_Q4_01 | O4: IDC7F_E08_Unity_880_1020502476_SAS | P4: 1 | Q4: 10.207.189.254 | R4: Yes | S4: anhtt69 | T4: 10.240.201.49/32 via 10.205.58.254 dev eth0 10.254.139.0/24 via 10.205.58.254 dev eth0 10.240.226.0/24 via 10.205.58.254 dev eth0 10.255.58.0/24 via 10.205.58.254 dev eth0 10.60.101.0/24 via 10.205.58.254 dev eth0 10.58.15.114/32 via 10.205.58.254 dev eth0 10.58.137.0/24 via 10.205.58.254 dev eth0 10.60.7.0/24 via 10.205.58.254 dev eth0 10.60.97.0/24 via 10.205.58.254 dev eth0 192.168.182.8/32 via 10.205.58.254 dev eth0 10.60.96.0/24 via 10.205.58.254 dev eth0 10.58.4.0/24 via 10.205.58.254 dev eth0 10.58.65.0/24 via 10.205.58.254 dev eth0 10.40.17.0/24 via 10.205.58.254 dev eth0 10.74.225.0/24 via 10.205.58.254 dev eth0 10.60.131.0/24 via 10.205.58.254 dev eth0 10.60.129.0/24 via 10.205.58.254 dev eth0 10.30.160.0/24 via 10.205.58.254 dev eth0 10.61.151.0/24 via 10.205.58.254 dev eth0 10.60.100.0/24 via 10.205.58.254 dev eth0 192.168.176.0/24 via 10.205.58.254 dev eth0 192.168.252.0/24 via 10.205.58.254 dev eth0 192.168.131.50/32 via 10.205.58.254 dev eth0 10.240.178.0/24 via 10.205.58.254 dev eth0 10.240.166.2/32 via 10.205.58.254 dev eth0 10.240.188.0/24 via 10.205.58.254 dev eth0 10.240.202.0/24 via 10.205.58.254 dev eth0 10.60.100.73/32 via 10.205.58.254 dev eth0 10.60.5.133/32 via 10.205.58.254 dev eth0 | V4: Yes | W4: Dau moi dich vu: tannph | X4: Các server đã cấp nhưng chưa dùng
A5: 3 | B5: Cloud_VTT | C5: MyCC | D5: appipccx | E5: mycc-appipccx-10205058091 | F5: 10.205.58.91/24 | G5: 10.207.189.7/24 10.52.125.8/24 171.229.16.35/24 | H5: CentOS_7_7_final | I5: 14 | J5: 54 | K5: 60 | L5: u01: 190 | N5: VTT_SAN_2021_Q4_01 | O5: IDC7F_E07_Unity_880_1020502474_SAS | P5: 1 | Q5: 10.207.189.254 | R5: Yes | S5: anhtt69 | T5: 10.240.201.49/32 via 10.205.58.254 dev eth0 10.254.139.0/24 via 10.205.58.254 dev eth0 10.240.226.0/24 via 10.205.58.254 dev eth0 10.255.58.0/24 via 10.205.58.254 dev eth0 10.60.101.0/24 via 10.205.58.254 dev eth0 10.58.15.114/32 via 10.205.58.254 dev eth0 10.58.137.0/24 via 10.205.58.254 dev eth0 10.60.7.0/24 via 10.205.58.254 dev eth0 10.60.97.0/24 via 10.205.58.254 dev eth0 192.168.182.8/32 via 10.205.58.254 dev eth0 10.60.96.0/24 via 10.205.58.254 dev eth0 10.58.4.0/24 via 10.205.58.254 dev eth0 10.58.65.0/24 via 10.205.58.254 dev eth0 10.40.17.0/24 via 10.205.58.254 dev eth0 10.74.225.0/24 via 10.205.58.254 dev eth0 10.60.131.0/24 via 10.205.58.254 dev eth0 10.60.129.0/24 via 10.205.58.254 dev eth0 10.30.160.0/24 via 10.205.58.254 dev eth0 10.61.151.0/24 via 10.205.58.254 dev eth0 10.60.100.0/24 via 10.205.58.254 dev eth0 192.168.176.0/24 via 10.205.58.254 dev eth0 192.168.252.0/24 via 10.205.58.254 dev eth0 192.168.131.50/32 via 10.205.58.254 dev eth0 10.240.178.0/24 via 10.205.58.254 dev eth0 10.240.166.2/32 via 10.205.58.254 dev eth0 10.240.188.0/24 via 10.205.58.254 dev eth0 10.240.202.0/24 via 10.205.58.254 dev eth0 10.60.100.73/32 via 10.205.58.254 dev eth0 10.60.5.133/32 via 10.205.58.254 dev eth0 | V5: Yes | W5: Dau moi dich vu: tannph | X5: Các server đã cấp nhưng chưa dùng
A6: 4 | B6: Cloud_VTT | C6: MyCC | D6: appipccx | E6: mycc-appipccx-10205058092 | F6: 10.205.58.92/24 | G6: 10.207.189.8/24 10.52.125.9/24 171.229.16.36/24 | H6: CentOS_7_7_final | I6: 14 | J6: 54 | K6: 60 | L6: u01: 190 | N6: VTT_SAN_2021_Q4_01 | O6: IDC7F_E08_Unity_880_1020502476_SAS | P6: 1 | Q6: 10.207.189.254 | R6: Yes | S6: anhtt69 | T6: 10.240.201.49/32 via 10.205.58.254 dev eth0 10.254.139.0/24 via 10.205.58.254 dev eth0 10.240.226.0/24 via 10.205.58.254 dev eth0 10.255.58.0/24 via 10.205.58.254 dev eth0 10.60.101.0/24 via 10.205.58.254 dev eth0 10.58.15.114/32 via 10.205.58.254 dev eth0 10.58.137.0/24 via 10.205.58.254 dev eth0 10.60.7.0/24 via 10.205.58.254 dev eth0 10.60.97.0/24 via 10.205.58.254 dev eth0 192.168.182.8/32 via 10.205.58.254 dev eth0 10.60.96.0/24 via 10.205.58.254 dev eth0 10.58.4.0/24 via 10.205.58.254 dev eth0 10.58.65.0/24 via 10.205.58.254 dev eth0 10.40.17.0/24 via 10.205.58.254 dev eth0 10.74.225.0/24 via 10.205.58.254 dev eth0 10.60.131.0/24 via 10.205.58.254 dev eth0 10.60.129.0/24 via 10.205.58.254 dev eth0 10.30.160.0/24 via 10.205.58.254 dev eth0 10.61.151.0/24 via 10.205.58.254 dev eth0 10.60.100.0/24 via 10.205.58.254 dev eth0 192.168.176.0/24 via 10.205.58.254 dev eth0 192.168.252.0/24 via 10.205.58.254 dev eth0 192.168.131.50/32 via 10.205.58.254 dev eth0 10.240.178.0/24 via 10.205.58.254 dev eth0 10.240.166.2/32 via 10.205.58.254 dev eth0 10.240.188.0/24 via 10.205.58.254 dev eth0 10.240.202.0/24 via 10.205.58.254 dev eth0 10.60.100.73/32 via 10.205.58.254 dev eth0 10.60.5.133/32 via 10.205.58.254 dev eth0 | V6: Yes | W6: Dau moi dich vu: tannph | X6: Các server đã cấp nhưng chưa dùng
A7: 5 | B7: Cloud_VTT | C7: MyCC | D7: appipccx | E7: mycc-appipccx-10205058093 | F7: 10.205.58.93/24 | G7: 10.207.189.9/24 10.52.125.10/24 171.229.16.37/24 | H7: CentOS_7_7_final | I7: 14 | J7: 54 | K7: 60 | L7: u01: 190 | N7: VTT_SAN_2021_Q4_01 | O7: IDC7F_E07_Unity_880_1020502474_SAS | P7: 1 | Q7: 10.207.189.254 | R7: Yes | S7: anhtt69 | T7: 10.240.201.49/32 via 10.205.58.254 dev eth0 10.254.139.0/24 via 10.205.58.254 dev eth0 10.240.226.0/24 via 10.205.58.254 dev eth0 10.255.58.0/24 via 10.205.58.254 dev eth0 10.60.101.0/24 via 10.205.58.254 dev eth0 10.58.15.114/32 via 10.205.58.254 dev eth0 10.58.137.0/24 via 10.205.58.254 dev eth0 10.60.7.0/24 via 10.205.58.254 dev eth0 10.60.97.0/24 via 10.205.58.254 dev eth0 192.168.182.8/32 via 10.205.58.254 dev eth0 10.60.96.0/24 via 10.205.58.254 dev eth0 10.58.4.0/24 via 10.205.58.254 dev eth0 10.58.65.0/24 via 10.205.58.254 dev eth0 10.40.17.0/24 via 10.205.58.254 dev eth0 10.74.225.0/24 via 10.205.58.254 dev eth0 10.60.131.0/24 via 10.205.58.254 dev eth0 10.60.129.0/24 via 10.205.58.254 dev eth0 10.30.160.0/24 via 10.205.58.254 dev eth0 10.61.151.0/24 via 10.205.58.254 dev eth0 10.60.100.0/24 via 10.205.58.254 dev eth0 192.168.176.0/24 via 10.205.58.254 dev eth0 192.168.252.0/24 via 10.205.58.254 dev eth0 192.168.131.50/32 via 10.205.58.254 dev eth0 10.240.178.0/24 via 10.205.58.254 dev eth0 10.240.166.2/32 via 10.205.58.254 dev eth0 10.240.188.0/24 via 10.205.58.254 dev eth0 10.240.202.0/24 via 10.205.58.254 dev eth0 10.60.100.73/32 via 10.205.58.254 dev eth0 10.60.5.133/32 via 10.205.58.254 dev eth0 | V7: Yes | W7: Dau moi dich vu: tannph | X7: Các server đã cấp nhưng chưa dùng
A8: 6 | B8: Cloud_VTT | C8: MyCC | D8: appipccx | E8: mycc-appipccx-10205058094 | F8: 10.205.58.94/24 | G8: 10.207.189.10/24 10.52.125.11/24 171.229.16.38/24 | H8: CentOS_7_7_final | I8: 14 | J8: 54 | K8: 60 | L8: u01: 190 | N8: VTT_SAN_2021_Q4_01 | O8: IDC7F_E08_Unity_880_1020502476_SAS | P8: 1 | Q8: 10.207.189.254 | R8: Yes | S8: anhtt69 | T8: 10.240.201.49/32 via 10.205.58.254 dev eth0 10.254.139.0/24 via 10.205.58.254 dev eth0 10.240.226.0/24 via 10.205.58.254 dev eth0 10.255.58.0/24 via 10.205.58.254 dev eth0 10.60.101.0/24 via 10.205.58.254 dev eth0 10.58.15.114/32 via 10.205.58.254 dev eth0 10.58.137.0/24 via 10.205.58.254 dev eth0 10.60.7.0/24 via 10.205.58.254 dev eth0 10.60.97.0/24 via 10.205.58.254 dev eth0 192.168.182.8/32 via 10.205.58.254 dev eth0 10.60.96.0/24 via 10.205.58.254 dev eth0 10.58.4.0/24 via 10.205.58.254 dev eth0 10.58.65.0/24 via 10.205.58.254 dev eth0 10.40.17.0/24 via 10.205.58.254 dev eth0 10.74.225.0/24 via 10.205.58.254 dev eth0 10.60.131.0/24 via 10.205.58.254 dev eth0 10.60.129.0/24 via 10.205.58.254 dev eth0 10.30.160.0/24 via 10.205.58.254 dev eth0 10.61.151.0/24 via 10.205.58.254 dev eth0 10.60.100.0/24 via 10.205.58.254 dev eth0 192.168.176.0/24 via 10.205.58.254 dev eth0 192.168.252.0/24 via 10.205.58.254 dev eth0 192.168.131.50/32 via 10.205.58.254 dev eth0 10.240.178.0/24 via 10.205.58.254 dev eth0 10.240.166.2/32 via 10.205.58.254 dev eth0 10.240.188.0/24 via 10.205.58.254 dev eth0 10.240.202.0/24 via 10.205.58.254 dev eth0 10.60.100.73/32 via 10.205.58.254 dev eth0 10.60.5.133/32 via 10.205.58.254 dev eth0 | V8: Yes | W8: Dau moi dich vu: tannph | X8: Các server đã cấp nhưng chưa dùng
A9: 7 | B9: Cloud_VTT | C9: MyCC | D9: appipcc1x | E9: mycc-appipcc1x-10205058095 | F9: 10.205.58.95/24 | G9: 10.207.189.11/24 10.207.192.43/24 | H9: CentOS_7_7_final | I9: 40 | J9: 26 | K9: 60 | L9: u01: 190 | M9: 5000 | N9: VTT_SAN_2021_Q4_01 | O9: IDC7F_E07_Unity_880_1020502474_SAS | P9: 1 | Q9: 10.207.189.254 | R9: Yes | S9: anhtt69 | T9: 10.240.201.49/32 via 10.205.58.254 dev eth0 10.254.139.0/24 via 10.205.58.254 dev eth0 10.240.226.0/24 via 10.205.58.254 dev eth0 10.255.58.0/24 via 10.205.58.254 dev eth0 10.60.101.0/24 via 10.205.58.254 dev eth0 10.58.15.114/32 via 10.205.58.254 dev eth0 10.58.137.0/24 via 10.205.58.254 dev eth0 10.60.7.0/24 via 10.205.58.254 dev eth0 10.60.97.0/24 via 10.205.58.254 dev eth0 192.168.182.8/32 via 10.205.58.254 dev eth0 10.60.96.0/24 via 10.205.58.254 dev eth0 10.58.4.0/24 via 10.205.58.254 dev eth0 10.58.65.0/24 via 10.205.58.254 dev eth0 10.40.17.0/24 via 10.205.58.254 dev eth0 10.74.225.0/24 via 10.205.58.254 dev eth0 10.60.131.0/24 via 10.205.58.254 dev eth0 10.60.129.0/24 via 10.205.58.254 dev eth0 10.30.160.0/24 via 10.205.58.254 dev eth0 10.61.151.0/24 via 10.205.58.254 dev eth0 10.60.100.0/24 via 10.205.58.254 dev eth0 192.168.176.0/24 via 10.205.58.254 dev eth0 192.168.252.0/24 via 10.205.58.254 dev eth0 192.168.131.50/32 via 10.205.58.254 dev eth0 10.240.178.0/24 via 10.205.58.254 dev eth0 10.240.166.2/32 via 10.205.58.254 dev eth0 10.240.188.0/24 via 10.205.58.254 dev eth0 10.240.202.0/24 via 10.205.58.254 dev eth0 10.60.100.73/32 via 10.205.58.254 dev eth0 10.60.5.133/32 via 10.205.58.254 dev eth0 | V9: Yes | W9: Dau moi dich vu: tannph | X9: Các server đã cấp nhưng chưa dùng
A10: 8 | B10: Cloud_VTT | C10: MyCC | D10: appipcc1x | E10: mycc-appipcc1x-10205058096 | F10: 10.205.58.96/24 | G10: 10.207.189.12/24 10.207.192.44/24 | H10: CentOS_7_7_final | I10: 40 | J10: 26 | K10: 60 | L10: u01: 190 | M10: 5000 | N10: VTT_SAN_2021_Q4_01 | O10: IDC7F_E08_Unity_880_1020502476_SAS | P10: 1 | Q10: 10.207.189.254 | R10: Yes | S10: anhtt69 | T10: 10.240.201.49/32 via 10.205.58.254 dev eth0 10.254.139.0/24 via 10.205.58.254 dev eth0 10.240.226.0/24 via 10.205.58.254 dev eth0 10.255.58.0/24 via 10.205.58.254 dev eth0 10.60.101.0/24 via 10.205.58.254 dev eth0 10.58.15.114/32 via 10.205.58.254 dev eth0 10.58.137.0/24 via 10.205.58.254 dev eth0 10.60.7.0/24 via 10.205.58.254 dev eth0 10.60.97.0/24 via 10.205.58.254 dev eth0 192.168.182.8/32 via 10.205.58.254 dev eth0 10.60.96.0/24 via 10.205.58.254 dev eth0 10.58.4.0/24 via 10.205.58.254 dev eth0 10.58.65.0/24 via 10.205.58.254 dev eth0 10.40.17.0/24 via 10.205.58.254 dev eth0 10.74.225.0/24 via 10.205.58.254 dev eth0 10.60.131.0/24 via 10.205.58.254 dev eth0 10.60.129.0/24 via 10.205.58.254 dev eth0 10.30.160.0/24 via 10.205.58.254 dev eth0 10.61.151.0/24 via 10.205.58.254 dev eth0 10.60.100.0/24 via 10.205.58.254 dev eth0 192.168.176.0/24 via 10.205.58.254 dev eth0 192.168.252.0/24 via 10.205.58.254 dev eth0 192.168.131.50/32 via 10.205.58.254 dev eth0 10.240.178.0/24 via 10.205.58.254 dev eth0 10.240.166.2/32 via 10.205.58.254 dev eth0 10.240.188.0/24 via 10.205.58.254 dev eth0 10.240.202.0/24 via 10.205.58.254 dev eth0 10.60.100.73/32 via 10.205.58.254 dev eth0 10.60.5.133/32 via 10.205.58.254 dev eth0 | V10: Yes | W10: Dau moi dich vu: tannph | X10: Các server đã cấp nhưng chưa dùng
A11: 9 | B11: Cloud_VTT | C11: MyCC | D11: appipcc1x | E11: mycc-appipcc1x-10205058097 | F11: 10.205.58.97/24 | G11: 10.207.189.13/24 10.207.192.45/24 | H11: CentOS_7_7_final | I11: 40 | J11: 26 | K11: 60 | L11: u01: 190 | M11: 5000 | N11: VTT_SAN_2021_Q4_01 | O11: IDC7F_E07_Unity_880_1020502474_SAS | P11: 1 | Q11: 10.207.189.254 | R11: Yes | S11: anhtt69 | T11: 10.240.201.49/32 via 10.205.58.254 dev eth0 10.254.139.0/24 via 10.205.58.254 dev eth0 10.240.226.0/24 via 10.205.58.254 dev eth0 10.255.58.0/24 via 10.205.58.254 dev eth0 10.60.101.0/24 via 10.205.58.254 dev eth0 10.58.15.114/32 via 10.205.58.254 dev eth0 10.58.137.0/24 via 10.205.58.254 dev eth0 10.60.7.0/24 via 10.205.58.254 dev eth0 10.60.97.0/24 via 10.205.58.254 dev eth0 192.168.182.8/32 via 10.205.58.254 dev eth0 10.60.96.0/24 via 10.205.58.254 dev eth0 10.58.4.0/24 via 10.205.58.254 dev eth0 10.58.65.0/24 via 10.205.58.254 dev eth0 10.40.17.0/24 via 10.205.58.254 dev eth0 10.74.225.0/24 via 10.205.58.254 dev eth0 10.60.131.0/24 via 10.205.58.254 dev eth0 10.60.129.0/24 via 10.205.58.254 dev eth0 10.30.160.0/24 via 10.205.58.254 dev eth0 10.61.151.0/24 via 10.205.58.254 dev eth0 10.60.100.0/24 via 10.205.58.254 dev eth0 192.168.176.0/24 via 10.205.58.254 dev eth0 192.168.252.0/24 via 10.205.58.254 dev eth0 192.168.131.50/32 via 10.205.58.254 dev eth0 10.240.178.0/24 via 10.205.58.254 dev eth0 10.240.166.2/32 via 10.205.58.254 dev eth0 10.240.188.0/24 via 10.205.58.254 dev eth0 10.240.202.0/24 via 10.205.58.254 dev eth0 10.60.100.73/32 via 10.205.58.254 dev eth0 10.60.5.133/32 via 10.205.58.254 dev eth0 | V11: Yes | W11: Dau moi dich vu: tannph | X11: Các server đã cấp nhưng chưa dùng
A12: 10 | B12: Cloud_VTT | C12: MyCC | D12: appipcc1x | E12: mycc-appipcc1x-10205058098 | F12: 10.205.58.98/24 | G12: 10.207.189.14/24 10.207.192.46/24 | H12: CentOS_7_7_final | I12: 40 | J12: 26 | K12: 60 | L12: u01: 190 | M12: 5000 | N12: VTT_SAN_2021_Q4_01 | O12: IDC7F_E08_Unity_880_1020502476_SAS | P12: 1 | Q12: 10.207.189.254 | R12: Yes | S12: anhtt69 | T12: 10.240.201.49/32 via 10.205.58.254 dev eth0 10.254.139.0/24 via 10.205.58.254 dev eth0 10.240.226.0/24 via 10.205.58.254 dev eth0 10.255.58.0/24 via 10.205.58.254 dev eth0 10.60.101.0/24 via 10.205.58.254 dev eth0 10.58.15.114/32 via 10.205.58.254 dev eth0 10.58.137.0/24 via 10.205.58.254 dev eth0 10.60.7.0/24 via 10.205.58.254 dev eth0 10.60.97.0/24 via 10.205.58.254 dev eth0 192.168.182.8/32 via 10.205.58.254 dev eth0 10.60.96.0/24 via 10.205.58.254 dev eth0 10.58.4.0/24 via 10.205.58.254 dev eth0 10.58.65.0/24 via 10.205.58.254 dev eth0 10.40.17.0/24 via 10.205.58.254 dev eth0 10.74.225.0/24 via 10.205.58.254 dev eth0 10.60.131.0/24 via 10.205.58.254 dev eth0 10.60.129.0/24 via 10.205.58.254 dev eth0 10.30.160.0/24 via 10.205.58.254 dev eth0 10.61.151.0/24 via 10.205.58.254 dev eth0 10.60.100.0/24 via 10.205.58.254 dev eth0 192.168.176.0/24 via 10.205.58.254 dev eth0 192.168.252.0/24 via 10.205.58.254 dev eth0 192.168.131.50/32 via 10.205.58.254 dev eth0 10.240.178.0/24 via 10.205.58.254 dev eth0 10.240.166.2/32 via 10.205.58.254 dev eth0 10.240.188.0/24 via 10.205.58.254 dev eth0 10.240.202.0/24 via 10.205.58.254 dev eth0 10.60.100.73/32 via 10.205.58.254 dev eth0 10.60.5.133/32 via 10.205.58.254 dev eth0 | V12: Yes | W12: Dau moi dich vu: tannph | X12: Các server đã cấp nhưng chưa dùng
